Workbook

Sheet Read Me
B2: Bluebell SaaS — Financial Model
B3: Investor & CFO workbook · 36-month operating history (Oct 2023 – Sep 2026)
B5: Purpose
B6: This workbook turns the raw monthly P&L into the unit economics and growth metrics an investor update requires, computed with live Excel formulas so the CFO can flex any input and see every dependent figure recalculate. The Input sheet holds the source data verbatim; every other sheet references it.
B8: How the model is built
B9: 1 Inputs are raw only.
B10: The Input sheet reproduces the source workbook verbatim. No figures are edited or smoothed.
B11: 2 Live formulas, not pasted values.
B12: Every metric on Model, Unit Economics and Rule of 40 is an Excel formula pointing at Input. Change a cell on Input and the whole model recalculates. The only hard-coded inputs are the opening customer count (120) and the assumed monthly discount rate on Projections.
B13: 3 Customer bridge.
B14: Opening base is 120 active customers at end-Sep-2023. Each month adds new_customers and subtracts churned_customers; the running balance drives ARPA, churn rate and LTV.
B15: 4 CAC / LTV convention.
... B30: Prepared 10 Sep 2026 · figures in USD unless noted · opening base 120 customers (end-Sep-2023).

Sheet Input
A1: Input — raw source data (financials.xlsx, sheet 'raw')
A2: Reproduced verbatim. This is the only place figures are entered.
A4: month | B4: mrr | C4: new_customers | D4: churned_customers | E4: cogs | F4: sales_marketing_spend | G4: headcount
A5: 2023-10 | B5: 22955.41 | C5: 14 | D5: 4 | E5: 6427.51 | F5: 12146.46 | G5: 9
A6: 2023-11 | B6: 25680.63 | C6: 14 | D6: 4 | E6: 7146.55 | F6: 13079.62 | G6: 10
A7: 2023-12 | B7: 27600.88 | C7: 17 | D7: 4 | E7: 7633.61 | F7: 15396.65 | G7: 10
A8: 2024-01 | B8: 29838.64 | C8: 15 | D8: 5 | E8: 8201.36 | F8: 13897.61 | G8: 11
A9: 2024-02 | B9: 31936.87 | C9: 15 | D9: 5 | E9: 8723.33 | F9: 14350.37 | G9: 12
A10: 2024-03 | B10: 34682.07 | C10: 18 | D10: 5 | E10: 9413.7 | F10: 17213.82 | G10: 13
A11: 2024-04 | B11: 37305.89 | C11: 20 | D11: 6 | E11: 10061.93 | F11: 19959.66 | G11: 13
A12: 2024-05 | B12: 40825.45 | C12: 20 | D12: 6 | E12: 10941.22 | F12: 18141.63 | G12: 14
A13: 2024-06 | B13: 44263.07 | C13: 22 | D13: 6 | E13: 11786.62 | F13: 19920.09 | G13: 15
A14: 2024-07 | B14: 47951.09 | C14: 19 | D14: 7 | E14: 12686.49 | F14: 18873.83 | G14: 15
A15: 2024-08 | B15: 51330.25 | C15: 23 | D15: 7 | E15: 13492.52 | F15: 22802.84 | G15: 16
A16: 2024-09 | B16: 54420.02 | C16: 24 | D16: 7 | E16: 14211.4 | F16: 24061.55 | G16: 17
... A40: 2026-09 | B40: 178857.07 | C40: 41 | D40: 15 | E40: 39348.56 | F40: 48686.47 | G40: 34
A42: Rows: | B42: 36
A43: Period: | B43: 2023-10 → 2026-09

Sheet Model
A1: Operating Model — monthly, Oct 2023 → Sep 2026
A2: All cells are formulas referencing Input. Opening customer base = 120 (end-Sep-2023).
A4: month | B4: customers_start | C4: new_customers | D4: churned_customers | E4: customers_end | F4: net_adds | G4: mrr | H4: arpa | I4: cogs | J4: gross_profit | K4: gross_margin | L4: sm_spend | M4: opex_total | N4: contribution_profit | O4: contribution_margin | P4: burn_or_profit | Q4: mrr_per_fte
A5: =Input!A5 | B5: =120 | C5: =Input!C5 | D5: =Input!D5 | E5: =B5+C5-D5 | F5: =C5-D5 | G5: =Input!B5 | H5: =IFERROR(G5/E5,0) | I5: =Input!E5 | J5: =G5-I5 | K5: =IFERROR(J5/G5,0) | L5: =Input!F5 | M5: =I5+L5 | N5: =G5-M5 | O5: =IFERROR(N5/G5,0) | P5: =N5 | Q5: =IFERROR(G5/Input!G5,0)
A6: =Input!A6 | B6: =E5 | C6: =Input!C6 | D6: =Input!D6 | E6: =B6+C6-D6 | F6: =C6-D6 | G6: =Input!B6 | H6: =IFERROR(G6/E6,0) | I6: =Input!E6 | J6: =G6-I6 | K6: =IFERROR(J6/G6,0) | L6: =Input!F6 | M6: =I6+L6 | N6: =G6-M6 | O6: =IFERROR(N6/G6,0) | P6: =N6 | Q6: =IFERROR(G6/Input!G6,0)
A7: =Input!A7 | B7: =E6 | C7: =Input!C7 | D7: =Input!D7 | E7: =B7+C7-D7 | F7: =C7-D7 | G7: =Input!B7 | H7: =IFERROR(G7/E7,0) | I7: =Input!E7 | J7: =G7-I7 | K7: =IFERROR(J7/G7,0) | L7: =Input!F7 | M7: =I7+L7 | N7: =G7-M7 | O7: =IFERROR(N7/G7,0) | P7: =N7 | Q7: =IFERROR(G7/Input!G7,0)
A8: =Input!A8 | B8: =E7 | C8: =Input!C8 | D8: =Input!D8 | E8: =B8+C8-D8 | F8: =C8-D8 | G8: =Input!B8 | H8: =IFERROR(G8/E8,0) | I8: =Input!E8 | J8: =G8-I8 | K8: =IFERROR(J8/G8,0) | L8: =Input!F8 | M8: =I8+L8 | N8: =G8-M8 | O8: =IFERROR(N8/G8,0) | P8: =N8 | Q8: =IFERROR(G8/Input!G8,0)
A9: =Input!A9 | B9: =E8 | C9: =Input!C9 | D9: =Input!D9 | E9: =B9+C9-D9 | F9: =C9-D9 | G9: =Input!B9 | H9: =IFERROR(G9/E9,0) | I9: =Input!E9 | J9: =G9-I9 | K9: =IFERROR(J9/G9,0) | L9: =Input!F9 | M9: =I9+L9 | N9: =G9-M9 | O9: =IFERROR(N9/G9,0) | P9: =N9 | Q9: =IFERROR(G9/Input!G9,0)
A10: =Input!A10 | B10: =E9 | C10: =Input!C10 | D10: =Input!D10 | E10: =B10+C10-D10 | F10: =C10-D10 | G10: =Input!B10 | H10: =IFERROR(G10/E10,0) | I10: =Input!E10 | J10: =G10-I10 | K10: =IFERROR(J10/G10,0) | L10: =Input!F10 | M10: =I10+L10 | N10: =G10-M10 | O10: =IFERROR(N10/G10,0) | P10: =N10 | Q10: =IFERROR(G10/Input!G10,0)
A11: =Input!A11 | B11: =E10 | C11: =Input!C11 | D11: =Input!D11 | E11: =B11+C11-D11 | F11: =C11-D11 | G11: =Input!B11 | H11: =IFERROR(G11/E11,0) | I11: =Input!E11 | J11: =G11-I11 | K11: =IFERROR(J11/G11,0) | L11: =Input!F11 | M11: =I11+L11 | N11: =G11-M11 | O11: =IFERROR(N11/G11,0) | P11: =N11 | Q11: =IFERROR(G11/Input!G11,0)
A12: =Input!A12 | B12: =E11 | C12: =Input!C12 | D12: =Input!D12 | E12: =B12+C12-D12 | F12: =C12-D12 | G12: =Input!B12 | H12: =IFERROR(G12/E12,0) | I12: =Input!E12 | J12: =G12-I12 | K12: =IFERROR(J12/G12,0) | L12: =Input!F12 | M12: =I12+L12 | N12: =G12-M12 | O12: =IFERROR(N12/G12,0) | P12: =N12 | Q12: =IFERROR(G12/Input!G12,0)
A13: =Input!A13 | B13: =E12 | C13: =Input!C13 | D13: =Input!D13 | E13: =B13+C13-D13 | F13: =C13-D13 | G13: =Input!B13 | H13: =IFERROR(G13/E13,0) | I13: =Input!E13 | J13: =G13-I13 | K13: =IFERROR(J13/G13,0) | L13: =Input!F13 | M13: =I13+L13 | N13: =G13-M13 | O13: =IFERROR(N13/G13,0) | P13: =N13 | Q13: =IFERROR(G13/Input!G13,0)
A14: =Input!A14 | B14: =E13 | C14: =Input!C14 | D14: =Input!D14 | E14: =B14+C14-D14 | F14: =C14-D14 | G14: =Input!B14 | H14: =IFERROR(G14/E14,0) | I14: =Input!E14 | J14: =G14-I14 | K14: =IFERROR(J14/G14,0) | L14: =Input!F14 | M14: =I14+L14 | N14: =G14-M14 | O14: =IFERROR(N14/G14,0) | P14: =N14 | Q14: =IFERROR(G14/Input!G14,0)
A15: =Input!A15 | B15: =E14 | C15: =Input!C15 | D15: =Input!D15 | E15: =B15+C15-D15 | F15: =C15-D15 | G15: =Input!B15 | H15: =IFERROR(G15/E15,0) | I15: =Input!E15 | J15: =G15-I15 | K15: =IFERROR(J15/G15,0) | L15: =Input!F15 | M15: =I15+L15 | N15: =G15-M15 | O15: =IFERROR(N15/G15,0) | P15: =N15 | Q15: =IFERROR(G15/Input!G15,0)
A16: =Input!A16 | B16: =E15 | C16: =Input!C16 | D16: =Input!D16 | E16: =B16+C16-D16 | F16: =C16-D16 | G16: =Input!B16 | H16: =IFERROR(G16/E16,0) | I16: =Input!E16 | J16: =G16-I16 | K16: =IFERROR(J16/G16,0) | L16: =Input!F16 | M16: =I16+L16 | N16: =G16-M16 | O16: =IFERROR(N16/G16,0) | P16: =N16 | Q16: =IFERROR(G16/Input!G16,0)
A17: =Input!A17 | B17: =E16 | C17: =Input!C17 | D17: =Input!D17 | E17: =B17+C17-D17 | F17: =C17-D17 | G17: =Input!B17 | H17: =IFERROR(G17/E17,0) | I17: =Input!E17 | J17: =G17-I17 | K17: =IFERROR(J17/G17,0) | L17: =Input!F17 | M17: =I17+L17 | N17: =G17-M17 | O17: =IFERROR(N17/G17,0) | P17: =N17 | Q17: =IFERROR(G17/Input!G17,0)
... A40: =Input!A40 | B40: =E39 | C40: =Input!C40 | D40: =Input!D40 | E40: =B40+C40-D40 | F40: =C40-D40 | G40: =Input!B40 | H40: =IFERROR(G40/E40,0) | I40: =Input!E40 | J40: =G40-I40 | K40: =IFERROR(J40/G40,0) | L40: =Input!F40 | M40: =I40+L40 | N40: =G40-M40 | O40: =IFERROR(N40/G40,0) | P40: =N40 | Q40: =IFERROR(G40/Input!G40,0)
A42: TTM (last 12 mo) | C42: =SUM(C29:C40) | D42: =SUM(D29:D40) | G42: =SUM(G29:G40) | I42: =SUM(I29:I40) | J42: =SUM(J29:J40) | L42: =SUM(L29:L40) | N42: =SUM(N29:N40)

Sheet Unit Economics
A1: Unit Economics — trailing 12-month rolling
A2: CAC = T12M S&M ÷ T12M new customers · LTV = ARPA × GM ÷ monthly churn (point-in-time) · Payback = CAC ÷ (ARPA × GM)
A4: month | B4: customers_end | C4: arpa | D4: gross_margin | E4: monthly_churn | F4: t12m_sm | G4: t12m_new | H4: cac | I4: ltv | J4: ltv_cac | K4: cac_payback_months
A5: =Model!A5 | B5: =Model!E5 | C5: =Model!H5 | D5: =Model!K5 | E5: =IFERROR(Model!D5/Model!B5,0) | F5: =SUM(Model!L5:L5) | G5: =SUM(Model!C5:C5) | H5: =IFERROR(F5/G5,0) | I5: =IFERROR(C5*D5/E5,0) | J5: =IFERROR(I5/H5,0) | K5: =IFERROR(H5/(C5*D5),0)
A6: =Model!A6 | B6: =Model!E6 | C6: =Model!H6 | D6: =Model!K6 | E6: =IFERROR(Model!D6/Model!B6,0) | F6: =SUM(Model!L5:L6) | G6: =SUM(Model!C5:C6) | H6: =IFERROR(F6/G6,0) | I6: =IFERROR(C6*D6/E6,0) | J6: =IFERROR(I6/H6,0) | K6: =IFERROR(H6/(C6*D6),0)
A7: =Model!A7 | B7: =Model!E7 | C7: =Model!H7 | D7: =Model!K7 | E7: =IFERROR(Model!D7/Model!B7,0) | F7: =SUM(Model!L5:L7) | G7: =SUM(Model!C5:C7) | H7: =IFERROR(F7/G7,0) | I7: =IFERROR(C7*D7/E7,0) | J7: =IFERROR(I7/H7,0) | K7: =IFERROR(H7/(C7*D7),0)
A8: =Model!A8 | B8: =Model!E8 | C8: =Model!H8 | D8: =Model!K8 | E8: =IFERROR(Model!D8/Model!B8,0) | F8: =SUM(Model!L5:L8) | G8: =SUM(Model!C5:C8) | H8: =IFERROR(F8/G8,0) | I8: =IFERROR(C8*D8/E8,0) | J8: =IFERROR(I8/H8,0) | K8: =IFERROR(H8/(C8*D8),0)
A9: =Model!A9 | B9: =Model!E9 | C9: =Model!H9 | D9: =Model!K9 | E9: =IFERROR(Model!D9/Model!B9,0) | F9: =SUM(Model!L5:L9) | G9: =SUM(Model!C5:C9) | H9: =IFERROR(F9/G9,0) | I9: =IFERROR(C9*D9/E9,0) | J9: =IFERROR(I9/H9,0) | K9: =IFERROR(H9/(C9*D9),0)
A10: =Model!A10 | B10: =Model!E10 | C10: =Model!H10 | D10: =Model!K10 | E10: =IFERROR(Model!D10/Model!B10,0) | F10: =SUM(Model!L5:L10) | G10: =SUM(Model!C5:C10) | H10: =IFERROR(F10/G10,0) | I10: =IFERROR(C10*D10/E10,0) | J10: =IFERROR(I10/H10,0) | K10: =IFERROR(H10/(C10*D10),0)
A11: =Model!A11 | B11: =Model!E11 | C11: =Model!H11 | D11: =Model!K11 | E11: =IFERROR(Model!D11/Model!B11,0) | F11: =SUM(Model!L5:L11) | G11: =SUM(Model!C5:C11) | H11: =IFERROR(F11/G11,0) | I11: =IFERROR(C11*D11/E11,0) | J11: =IFERROR(I11/H11,0) | K11: =IFERROR(H11/(C11*D11),0)
A12: =Model!A12 | B12: =Model!E12 | C12: =Model!H12 | D12: =Model!K12 | E12: =IFERROR(Model!D12/Model!B12,0) | F12: =SUM(Model!L5:L12) | G12: =SUM(Model!C5:C12) | H12: =IFERROR(F12/G12,0) | I12: =IFERROR(C12*D12/E12,0) | J12: =IFERROR(I12/H12,0) | K12: =IFERROR(H12/(C12*D12),0)
A13: =Model!A13 | B13: =Model!E13 | C13: =Model!H13 | D13: =Model!K13 | E13: =IFERROR(Model!D13/Model!B13,0) | F13: =SUM(Model!L5:L13) | G13: =SUM(Model!C5:C13) | H13: =IFERROR(F13/G13,0) | I13: =IFERROR(C13*D13/E13,0) | J13: =IFERROR(I13/H13,0) | K13: =IFERROR(H13/(C13*D13),0)
A14: =Model!A14 | B14: =Model!E14 | C14: =Model!H14 | D14: =Model!K14 | E14: =IFERROR(Model!D14/Model!B14,0) | F14: =SUM(Model!L5:L14) | G14: =SUM(Model!C5:C14) | H14: =IFERROR(F14/G14,0) | I14: =IFERROR(C14*D14/E14,0) | J14: =IFERROR(I14/H14,0) | K14: =IFERROR(H14/(C14*D14),0)
A15: =Model!A15 | B15: =Model!E15 | C15: =Model!H15 | D15: =Model!K15 | E15: =IFERROR(Model!D15/Model!B15,0) | F15: =SUM(Model!L5:L15) | G15: =SUM(Model!C5:C15) | H15: =IFERROR(F15/G15,0) | I15: =IFERROR(C15*D15/E15,0) | J15: =IFERROR(I15/H15,0) | K15: =IFERROR(H15/(C15*D15),0)
A16: =Model!A16 | B16: =Model!E16 | C16: =Model!H16 | D16: =Model!K16 | E16: =IFERROR(Model!D16/Model!B16,0) | F16: =SUM(Model!L5:L16) | G16: =SUM(Model!C5:C16) | H16: =IFERROR(F16/G16,0) | I16: =IFERROR(C16*D16/E16,0) | J16: =IFERROR(I16/H16,0) | K16: =IFERROR(H16/(C16*D16),0)
A17: =Model!A17 | B17: =Model!E17 | C17: =Model!H17 | D17: =Model!K17 | E17: =IFERROR(Model!D17/Model!B17,0) | F17: =SUM(Model!L6:L17) | G17: =SUM(Model!C6:C17) | H17: =IFERROR(F17/G17,0) | I17: =IFERROR(C17*D17/E17,0) | J17: =IFERROR(I17/H17,0) | K17: =IFERROR(H17/(C17*D17),0)
A18: =Model!A18 | B18: =Model!E18 | C18: =Model!H18 | D18: =Model!K18 | E18: =IFERROR(Model!D18/Model!B18,0) | F18: =SUM(Model!L7:L18) | G18: =SUM(Model!C7:C18) | H18: =IFERROR(F18/G18,0) | I18: =IFERROR(C18*D18/E18,0) | J18: =IFERROR(I18/H18,0) | K18: =IFERROR(H18/(C18*D18),0)
A19: =Model!A19 | B19: =Model!E19 | C19: =Model!H19 | D19: =Model!K19 | E19: =IFERROR(Model!D19/Model!B19,0) | F19: =SUM(Model!L8:L19) | G19: =SUM(Model!C8:C19) | H19: =IFERROR(F19/G19,0) | I19: =IFERROR(C19*D19/E19,0) | J19: =IFERROR(I19/H19,0) | K19: =IFERROR(H19/(C19*D19),0)
A20: =Model!A20 | B20: =Model!E20 | C20: =Model!H20 | D20: =Model!K20 | E20: =IFERROR(Model!D20/Model!B20,0) | F20: =SUM(Model!L9:L20) | G20: =SUM(Model!C9:C20) | H20: =IFERROR(F20/G20,0) | I20: =IFERROR(C20*D20/E20,0) | J20: =IFERROR(I20/H20,0) | K20: =IFERROR(H20/(C20*D20),0)
A21: =Model!A21 | B21: =Model!E21 | C21: =Model!H21 | D21: =Model!K21 | E21: =IFERROR(Model!D21/Model!B21,0) | F21: =SUM(Model!L10:L21) | G21: =SUM(Model!C10:C21) | H21: =IFERROR(F21/G21,0) | I21: =IFERROR(C21*D21/E21,0) | J21: =IFERROR(I21/H21,0) | K21: =IFERROR(H21/(C21*D21),0)
A22: =Model!A22 | B22: =Model!E22 | C22: =Model!H22 | D22: =Model!K22 | E22: =IFERROR(Model!D22/Model!B22,0) | F22: =SUM(Model!L11:L22) | G22: =SUM(Model!C11:C22) | H22: =IFERROR(F22/G22,0) | I22: =IFERROR(C22*D22/E22,0) | J22: =IFERROR(I22/H22,0) | K22: =IFERROR(H22/(C22*D22),0)
A23: =Model!A23 | B23: =Model!E23 | C23: =Model!H23 | D23: =Model!K23 | E23: =IFERROR(Model!D23/Model!B23,0) | F23: =SUM(Model!L12:L23) | G23: =SUM(Model!C12:C23) | H23: =IFERROR(F23/G23,0) | I23: =IFERROR(C23*D23/E23,0) | J23: =IFERROR(I23/H23,0) | K23: =IFERROR(H23/(C23*D23),0)
A24: =Model!A24 | B24: =Model!E24 | C24: =Model!H24 | D24: =Model!K24 | E24: =IFERROR(Model!D24/Model!B24,0) | F24: =SUM(Model!L13:L24) | G24: =SUM(Model!C13:C24) | H24: =IFERROR(F24/G24,0) | I24: =IFERROR(C24*D24/E24,0) | J24: =IFERROR(I24/H24,0) | K24: =IFERROR(H24/(C24*D24),0)
A25: =Model!A25 | B25: =Model!E25 | C25: =Model!H25 | D25: =Model!K25 | E25: =IFERROR(Model!D25/Model!B25,0) | F25: =SUM(Model!L14:L25) | G25: =SUM(Model!C14:C25) | H25: =IFERROR(F25/G25,0) | I25: =IFERROR(C25*D25/E25,0) | J25: =IFERROR(I25/H25,0) | K25: =IFERROR(H25/(C25*D25),0)
A26: =Model!A26 | B26: =Model!E26 | C26: =Model!H26 | D26: =Model!K26 | E26: =IFERROR(Model!D26/Model!B26,0) | F26: =SUM(Model!L15:L26) | G26: =SUM(Model!C15:C26) | H26: =IFERROR(F26/G26,0) | I26: =IFERROR(C26*D26/E26,0) | J26: =IFERROR(I26/H26,0) | K26: =IFERROR(H26/(C26*D26),0)
A27: =Model!A27 | B27: =Model!E27 | C27: =Model!H27 | D27: =Model!K27 | E27: =IFERROR(Model!D27/Model!B27,0) | F27: =SUM(Model!L16:L27) | G27: =SUM(Model!C16:C27) | H27: =IFERROR(F27/G27,0) | I27: =IFERROR(C27*D27/E27,0) | J27: =IFERROR(I27/H27,0) | K27: =IFERROR(H27/(C27*D27),0)
... A40: =Model!A40 | B40: =Model!E40 | C40: =Model!H40 | D40: =Model!K40 | E40: =IFERROR(Model!D40/Model!B40,0) | F40: =SUM(Model!L29:L40) | G40: =SUM(Model!C29:C40) | H40: =IFERROR(F40/G40,0) | I40: =IFERROR(C40*D40/E40,0) | J40: =IFERROR(I40/H40,0) | K40: =IFERROR(H40/(C40*D40),0)
A43: Quarter-end summary (trailing-12-month unit economics)
A44: month | B44: customers_end | C44: arpa | D44: gross_margin | E44: monthly_churn | F44: cac | G44: ltv | H44: ltv_cac | I44: payback_m
A45: =A7 | B45: =B7 | C45: =C7 | D45: =D7 | E45: =E7 | F45: =H7 | G45: =I7 | H45: =J7 | I45: =K7
A46: =A10 | B46: =B10 | C46: =C10 | D46: =D10 | E46: =E10 | F46: =H10 | G46: =I10 | H46: =J10 | I46: =K10
A47: =A13 | B47: =B13 | C47: =C13 | D47: =D13 | E47: =E13 | F47: =H13 | G47: =I13 | H47: =J13 | I47: =K13
A48: =A16 | B48: =B16 | C48: =C16 | D48: =D16 | E48: =E16 | F48: =H16 | G48: =I16 | H48: =J16 | I48: =K16
A49: =A19 | B49: =B19 | C49: =C19 | D49: =D19 | E49: =E19 | F49: =H19 | G49: =I19 | H49: =J19 | I49: =K19
A50: =A22 | B50: =B22 | C50: =C22 | D50: =D22 | E50: =E22 | F50: =H22 | G50: =I22 | H50: =J22 | I50: =K22
A51: =A25 | B51: =B25 | C51: =C25 | D51: =D25 | E51: =E25 | F51: =H25 | G51: =I25 | H51: =J25 | I51: =K25
A52: =A28 | B52: =B28 | C52: =C28 | D52: =D28 | E52: =E28 | F52: =H28 | G52: =I28 | H52: =J28 | I52: =K28
A53: =A31 | B53: =B31 | C53: =C31 | D53: =D31 | E53: =E31 | F53: =H31 | G53: =I31 | H53: =J31 | I53: =K31
A54: =A34 | B54: =B34 | C54: =C34 | D54: =D34 | E54: =E34 | F54: =H34 | G54: =I34 | H54: =J34 | I54: =K34
A55: =A37 | B55: =B37 | C55: =C37 | D55: =D37 | E55: =E37 | F55: =H37 | G55: =I37 | H55: =J37 | I55: =K37
...

Sheet Rule of 40
A1: Rule of 40 — growth + margin, trailing 12-month
A2: Growth = TTM MRR ÷ prior-TTM MRR − 1 · Margin = TTM contribution margin · Score = growth% + margin%
A4: month | B4: ttm_mrr | C4: prior_ttm_mrr | D4: growth_yoy | E4: ttm_contrib_margin | F4: rule_of_40
A5: =Model!A5 | B5: =SUM(Model!G5:G5) | C5: =0 | D5: =0 | E5: =IFERROR(SUM(Model!N-6:N5)/SUM(Model!G-6:G5),0) | F5: =D5+E5
A6: =Model!A6 | B6: =SUM(Model!G5:G6) | C6: =0 | D6: =0 | E6: =IFERROR(SUM(Model!N-5:N6)/SUM(Model!G-5:G6),0) | F6: =D6+E6
A7: =Model!A7 | B7: =SUM(Model!G5:G7) | C7: =0 | D7: =0 | E7: =IFERROR(SUM(Model!N-4:N7)/SUM(Model!G-4:G7),0) | F7: =D7+E7
A8: =Model!A8 | B8: =SUM(Model!G5:G8) | C8: =0 | D8: =0 | E8: =IFERROR(SUM(Model!N-3:N8)/SUM(Model!G-3:G8),0) | F8: =D8+E8
A9: =Model!A9 | B9: =SUM(Model!G5:G9) | C9: =0 | D9: =0 | E9: =IFERROR(SUM(Model!N-2:N9)/SUM(Model!G-2:G9),0) | F9: =D9+E9
A10: =Model!A10 | B10: =SUM(Model!G5:G10) | C10: =0 | D10: =0 | E10: =IFERROR(SUM(Model!N-1:N10)/SUM(Model!G-1:G10),0) | F10: =D10+E10
A11: =Model!A11 | B11: =SUM(Model!G5:G11) | C11: =0 | D11: =0 | E11: =IFERROR(SUM(Model!N0:N11)/SUM(Model!G0:G11),0) | F11: =D11+E11
A12: =Model!A12 | B12: =SUM(Model!G5:G12) | C12: =0 | D12: =0 | E12: =IFERROR(SUM(Model!N1:N12)/SUM(Model!G1:G12),0) | F12: =D12+E12
A13: =Model!A13 | B13: =SUM(Model!G5:G13) | C13: =0 | D13: =0 | E13: =IFERROR(SUM(Model!N2:N13)/SUM(Model!G2:G13),0) | F13: =D13+E13
A14: =Model!A14 | B14: =SUM(Model!G5:G14) | C14: =0 | D14: =0 | E14: =IFERROR(SUM(Model!N3:N14)/SUM(Model!G3:G14),0) | F14: =D14+E14
A15: =Model!A15 | B15: =SUM(Model!G5:G15) | C15: =0 | D15: =0 | E15: =IFERROR(SUM(Model!N4:N15)/SUM(Model!G4:G15),0) | F15: =D15+E15
A16: =Model!A16 | B16: =SUM(Model!G5:G16) | C16: =SUM(Model!G-7:G4) | D16: =IFERROR(B16/C16-1,0) | E16: =IFERROR(SUM(Model!N5:N16)/SUM(Model!G5:G16),0) | F16: =D16+E16
A17: =Model!A17 | B17: =SUM(Model!G6:G17) | C17: =SUM(Model!G-6:G5) | D17: =IFERROR(B17/C17-1,0) | E17: =IFERROR(SUM(Model!N6:N17)/SUM(Model!G6:G17),0) | F17: =D17+E17
A18: =Model!A18 | B18: =SUM(Model!G7:G18) | C18: =SUM(Model!G-5:G6) | D18: =IFERROR(B18/C18-1,0) | E18: =IFERROR(SUM(Model!N7:N18)/SUM(Model!G7:G18),0) | F18: =D18+E18
A19: =Model!A19 | B19: =SUM(Model!G8:G19) | C19: =SUM(Model!G-4:G7) | D19: =IFERROR(B19/C19-1,0) | E19: =IFERROR(SUM(Model!N8:N19)/SUM(Model!G8:G19),0) | F19: =D19+E19
A20: =Model!A20 | B20: =SUM(Model!G9:G20) | C20: =SUM(Model!G-3:G8) | D20: =IFERROR(B20/C20-1,0) | E20: =IFERROR(SUM(Model!N9:N20)/SUM(Model!G9:G20),0) | F20: =D20+E20
A21: =Model!A21 | B21: =SUM(Model!G10:G21) | C21: =SUM(Model!G-2:G9) | D21: =IFERROR(B21/C21-1,0) | E21: =IFERROR(SUM(Model!N10:N21)/SUM(Model!G10:G21),0) | F21: =D21+E21
A22: =Model!A22 | B22: =SUM(Model!G11:G22) | C22: =SUM(Model!G-1:G10) | D22: =IFERROR(B22/C22-1,0) | E22: =IFERROR(SUM(Model!N11:N22)/SUM(Model!G11:G22),0) | F22: =D22+E22
A23: =Model!A23 | B23: =SUM(Model!G12:G23) | C23: =SUM(Model!G0:G11) | D23: =IFERROR(B23/C23-1,0) | E23: =IFERROR(SUM(Model!N12:N23)/SUM(Model!G12:G23),0) | F23: =D23+E23
A24: =Model!A24 | B24: =SUM(Model!G13:G24) | C24: =SUM(Model!G1:G12) | D24: =IFERROR(B24/C24-1,0) | E24: =IFERROR(SUM(Model!N13:N24)/SUM(Model!G13:G24),0) | F24: =D24+E24
A25: =Model!A25 | B25: =SUM(Model!G14:G25) | C25: =SUM(Model!G2:G13) | D25: =IFERROR(B25/C25-1,0) | E25: =IFERROR(SUM(Model!N14:N25)/SUM(Model!G14:G25),0) | F25: =D25+E25
A26: =Model!A26 | B26: =SUM(Model!G15:G26) | C26: =SUM(Model!G3:G14) | D26: =IFERROR(B26/C26-1,0) | E26: =IFERROR(SUM(Model!N15:N26)/SUM(Model!G15:G26),0) | F26: =D26+E26
A27: =Model!A27 | B27: =SUM(Model!G16:G27) | C27: =SUM(Model!G4:G15) | D27: =IFERROR(B27/C27-1,0) | E27: =IFERROR(SUM(Model!N16:N27)/SUM(Model!G16:G27),0) | F27: =D27+E27
A28: =Model!A28 | B28: =SUM(Model!G17:G28) | C28: =SUM(Model!G5:G16) | D28: =IFERROR(B28/C28-1,0) | E28: =IFERROR(SUM(Model!N17:N28)/SUM(Model!G17:G28),0) | F28: =D28+E28
A29: =Model!A29 | B29: =SUM(Model!G18:G29) | C29: =SUM(Model!G6:G17) | D29: =IFERROR(B29/C29-1,0) | E29: =IFERROR(SUM(Model!N18:N29)/SUM(Model!G18:G29),0) | F29: =D29+E29
A30: =Model!A30 | B30: =SUM(Model!G19:G30) | C30: =SUM(Model!G7:G18) | D30: =IFERROR(B30/C30-1,0) | E30: =IFERROR(SUM(Model!N19:N30)/SUM(Model!G19:G30),0) | F30: =D30+E30
A31: =Model!A31 | B31: =SUM(Model!G20:G31) | C31: =SUM(Model!G8:G19) | D31: =IFERROR(B31/C31-1,0) | E31: =IFERROR(SUM(Model!N20:N31)/SUM(Model!G20:G31),0) | F31: =D31+E31
A32: =Model!A32 | B32: =SUM(Model!G21:G32) | C32: =SUM(Model!G9:G20) | D32: =IFERROR(B32/C32-1,0) | E32: =IFERROR(SUM(Model!N21:N32)/SUM(Model!G21:G32),0) | F32: =D32+E32
A33: =Model!A33 | B33: =SUM(Model!G22:G33) | C33: =SUM(Model!G10:G21) | D33: =IFERROR(B33/C33-1,0) | E33: =IFERROR(SUM(Model!N22:N33)/SUM(Model!G22:G33),0) | F33: =D33+E33
A34: =Model!A34 | B34: =SUM(Model!G23:G34) | C34: =SUM(Model!G11:G22) | D34: =IFERROR(B34/C34-1,0) | E34: =IFERROR(SUM(Model!N23:N34)/SUM(Model!G23:G34),0) | F34: =D34+E34
A35: =Model!A35 | B35: =SUM(Model!G24:G35) | C35: =SUM(Model!G12:G23) | D35: =IFERROR(B35/C35-1,0) | E35: =IFERROR(SUM(Model!N24:N35)/SUM(Model!G24:G35),0) | F35: =D35+E35
... A40: =Model!A40 | B40: =SUM(Model!G29:G40) | C40: =SUM(Model!G17:G28) | D40: =IFERROR(B40/C40-1,0) | E40: =IFERROR(SUM(Model!N29:N40)/SUM(Model!G29:G40),0) | F40: =D40+E40
A42: Latest TTM | B42: =B40 | D42: =D40 | E42: =E40 | F42: =F40

Sheet Reconciliation
A1: Reconciliation — model vs last quarter's board deck (slide 7)
A2: Board deck slide 7 is labelled 'end of Q2' (Jun-2026). Figures below compare the deck's stated values to this model's computed values for the same period.
B4: Metric | C4: Board deck (slide 7) | D4: This model | E4: Δ | F4: Note
B5: CAC (TTM) | C5: 1583 | D5: ='Unit Economics'!H37 | E5: =C5-D5 | F5: Deck states $1,583; model computes ~$1,157. The deck's CAC does not tie to any trailing window on the source data — closest single-month CAC (Jun-2026) is ~$1,263, still not $1,583. Likely a prior-period figure or a different S&M basis.
B6: LTV | C6: 8019.93 | D6: ='Unit Economics'!I37 | E6: =C6-D6 | F6: Deck states $8,019.93; model computes ~$7,743 (TTM-average churn) or ~$8,472 (point-in-time end-month churn). The deck value falls between the two conventions — it does not reproduce under either standard method.
B7: CAC payback (months) | C7: 6.44 | D7: ='Unit Economics'!K37 | E7: =C7-D7 | F7: Deck states 6.44; model computes ~6.35. Small (~0.1m) difference, consistent with the LTV/churn method above.
B8: ARPA | C8: 236.27 | D8: ='Unit Economics'!C37 | E8: =C8-D8 | F8: Deck states $236.27 — but that is the ARPA for Sep-2026 (end of Q3), NOT Jun-2026 ($235.13). The deck appears to have used a later or restated customer/MRR figure than the period it labels.
B10: Bottom line
B11: Three of the four slide-7 figures do not reproduce from the source data for the stated period (Jun-2026). The ARPA figure ($236.27) matches Sep-2026, not Jun-2026 — suggesting the deck either pulled a later snapshot or mixed period labels. The CAC figure ($1,583) does not tie to any trailing window in the data. Recommend re-cutting slide 7 against this model before the investor update goes out.

Sheet Projections
A1: Projections — 6-month forward look (Oct 2026 → Mar 2027)
A2: Assumptions: MRR follows a 3-month linear trend; churn rate = 12-month trailing average; new customers = prior 3-month average; S&M scales with MRR at the 12-month trailing ratio. Not guidance.
A4: month | B4: mrr_projected | C4: customers_end | D4: arpa | E4: new_customers | F4: churned_customers | G4: cac | H4: gross_margin
B5: =Model!G40+(Model!G40-Model!G38)/2 | C5: =Model!E40+AVERAGE(Model!C38:C40)-Model!E40*AVERAGE('Unit Economics'!E17:E28) | D5: =IFERROR(B5/C5,0) | E5: =AVERAGE(Model!C38:C40) | F5: =ROUND(C5*AVERAGE('Unit Economics'!E17:E28),0) | G5: =IFERROR(AVERAGE(Model!L29:L40)/AVERAGE(Model!C29:C40),0) | H5: =AVERAGE(Model!K29:K40)
B6: =B5+(Model!G40-Model!G38)/2 | C6: =C5+AVERAGE(Model!C38:C40)-C5*AVERAGE('Unit Economics'!E17:E28) | D6: =IFERROR(B6/C6,0) | E6: =AVERAGE(Model!C38:C40) | F6: =ROUND(C6*AVERAGE('Unit Economics'!E17:E28),0) | G6: =IFERROR(AVERAGE(Model!L29:L40)/AVERAGE(Model!C29:C40),0) | H6: =AVERAGE(Model!K29:K40)
B7: =B6+(Model!G40-Model!G38)/2 | C7: =C6+AVERAGE(Model!C38:C40)-C6*AVERAGE('Unit Economics'!E17:E28) | D7: =IFERROR(B7/C7,0) | E7: =AVERAGE(Model!C38:C40) | F7: =ROUND(C7*AVERAGE('Unit Economics'!E17:E28),0) | G7: =IFERROR(AVERAGE(Model!L29:L40)/AVERAGE(Model!C29:C40),0) | H7: =AVERAGE(Model!K29:K40)
B8: =B7+(Model!G40-Model!G38)/2 | C8: =C7+AVERAGE(Model!C38:C40)-C7*AVERAGE('Unit Economics'!E17:E28) | D8: =IFERROR(B8/C8,0) | E8: =AVERAGE(Model!C38:C40) | F8: =ROUND(C8*AVERAGE('Unit Economics'!E17:E28),0) | G8: =IFERROR(AVERAGE(Model!L29:L40)/AVERAGE(Model!C29:C40),0) | H8: =AVERAGE(Model!K29:K40)
B9: =B8+(Model!G40-Model!G38)/2 | C9: =C8+AVERAGE(Model!C38:C40)-C8*AVERAGE('Unit Economics'!E17:E28) | D9: =IFERROR(B9/C9,0) | E9: =AVERAGE(Model!C38:C40) | F9: =ROUND(C9*AVERAGE('Unit Economics'!E17:E28),0) | G9: =IFERROR(AVERAGE(Model!L29:L40)/AVERAGE(Model!C29:C40),0) | H9: =AVERAGE(Model!K29:K40)
B10: =B9+(Model!G40-Model!G38)/2 | C10: =C9+AVERAGE(Model!C38:C40)-C9*AVERAGE('Unit Economics'!E17:E28) | D10: =IFERROR(B10/C10,0) | E10: =AVERAGE(Model!C38:C40) | F10: =ROUND(C10*AVERAGE('Unit Economics'!E17:E28),0) | G10: =IFERROR(AVERAGE(Model!L29:L40)/AVERAGE(Model!C29:C40),0) | H10: =AVERAGE(Model!K29:K40)
A12: Assumptions
A13: MRR trend slope | D13: =(Model!G40-Model!G38)/2
A14: Avg monthly churn (TTM) | D14: =AVERAGE('Unit Economics'!E17:E28)
A15: Avg new customers (last 3mo) | D15: =AVERAGE(Model!C38:C40)
A16: Opening customers (Sep-2026) | D16: =Model!E40
A18: Note: Projections are directional, not guidance. Refresh assumptions before circulating externally.
